Workbook

Sheet PFS
A1: PRESENCE FACTORS SCALE (PFS)
A3: Category | B3: Factor | C3: Description | D3: Level | E3: Value
A4: Engagement | B4: Inclusiveness | C4: The degree to which physical reality is excluded | D4: Select | E4: =IF(D4=Engagemmmment!D3,0,IF(D4=Engagemmmment!D4,2,IF(D4=Engagemmmment!D5,5,IF(D4=Engagemmmment!D6,7)))) -> 0
B6: Narrative | C6: The story designed to be experienced virtually by the user | D6: Select | E6: =IF(D6=Engagemmmment!D8,0,IF(D6=Engagemmmment!D9,2.5,IF(D6=Engagemmmment!D10,5,IF(D6=Engagemmmment!D11,6.5)))) -> 0
B8: Attention | C8: The degree to which the virtual environment retains the user's attention | D8: Select | E8: =IF(D8=Engagemmmment!D13,0,IF(D8=Engagemmmment!D14,2.5,IF(D8=Engagemmmment!D15,5,IF(D8=Engagemmmment!D16,6,IF(D8=Engagemmmment!D17,7))))) -> 0
B10: Emotion | C10: The emotions (Anger, Sadness, Happiness, Disgust, Surprise, Fear) experienced by the user in the virtual environment | D10: Select | E10: =IF(D10=Engagemmmment!D19,0,IF(D10=Engagemmmment!D20,1,IF(D10=Engagemmmment!D21,3,IF(D10=Engagemmmment!D22,5,IF(D10=Engagemmmment!D23,7))))) -> 0
B12: Task | C12: The act of doing something in the virtual environment | D12: Select | E12: =IF(D12=Engagemmmment!D25,0,IF(D12=Engagemmmment!D26,1,IF(D12=Engagemmmment!D27,3,IF(D12=Engagemmmment!D28,5,IF(D12=Engagemmmment!D29,7))))) -> 0
B14: Copresence | C14: The feeling of being with another in the virtual environment | D14: Select | E14: =IF(D14=Engagemmmment!D31,0,IF(D14=Engagemmmment!D32,1,IF(D14=Engagemmmment!D33,4,IF(D14=Engagemmmment!D34,7)))) -> 0
B16: Social presence | C16: The act of interacting with another in the virtual environment | D16: Select | E16: =IF(D16=Engagemmmment!D36,0,IF(D16=Engagemmmment!D37,1,IF(D16=Engagemmmment!D38,3,IF(D16=Engagemmmment!D39,5,IF(D16=Engagemmmment!D40,7))))) -> 0
E17: =AVERAGE(E4:E16) -> 0
A19: Interactive Fidelity | B19: Manipulation | C19: The ability of the virtual environment to be modified by user actions | D19: Select | E19: =IF(D19=Interactive!D2,0,IF(D19=Interactive!D3,1,IF(D19=Interactive!D4,4.5,IF(D19=Interactive!D5,5.5,IF(D19=Interactive!D6,7))))) -> 0
B21: Travel | C21: The way to navigate in the virtual environment | D21: Select | E21: =IF(D21=Interactive!D8,0,IF(D21=Interactive!D9,1,IF(D21=Interactive!D10,2,IF(D21=Interactive!D11,5,IF(D21=Interactive!D12,7,IF(D21=#REF!,6,IF(D21=#REF!,7,IF(D21=#REF!,7)))))))) -> 0
E22: =AVERAGE(E19:E21) -> 0
A24: Sensorial Fidelity | B24: Inclusiveness | C24: The number of external devices required | D24: Select | E24: =IF(D24=Sensorial!D3,0,IF(D24=Sensorial!D4,1.5,IF(D24=Sensorial!D5,3.5,IF(D24=Sensorial!D6,5.5,IF(D24=Sensorial!D7,7))))) -> 0
B26: Proprioception | C26: The sense of self-movement and body position | D26: Select | E26: =IF(D26=Sensorial!D9,0,IF(D26=Sensorial!D10,1,IF(D26=Sensorial!D11,2.5,IF(D26=Sensorial!D12,4.5,IF(D26=Sensorial!D13,6.5))))) -> 0
B28: Body Ownership | C28: The sense of body ownership in the virtual environment | D28: Select | E28: =IF(D28=Sensorial!D15,0,IF(D28=Sensorial!D16,1.5,IF(D28=Sensorial!D17,4.5,IF(D28=Sensorial!D18,7)))) -> 0
B30: Latency | C30: The delay between the user action and the reaction of the virtual environment | D30: Select | E30: =IF(D30=Sensorial!D20,0,IF(D30=Sensorial!D21,1.5,IF(D30=Sensorial!D22,4.5,IF(D30=Sensorial!D23,7)))) -> 0
B32: Transition | C32: The change of state between the real and virtual world | D32: Select | E32: =IF(D32=Sensorial!D25,0,IF(D32=Sensorial!D26,4,IF(D32=Sensorial!D27,7))) -> 0
B34: Synchronization | C34: The coordination between user actions and all virtual environment outputs | D34: Select | E34: =IF(D34=Sensorial!D29,0,IF(D34=Sensorial!D30,3,IF(D34=Sensorial!D31,6.5))) -> 0
B36: Plausibility | C36: The extent to which virutal environment is considered admissible | D36: Select | E36: =IF(D36=Sensorial!D33,0,IF(D36=Sensorial!D34,3,IF(D36=Sensorial!D35,6.5))) -> 0
B38: Visual Realism | C38: To what extent does the virtual environment looks visually real | D38: Select | E38: =IF(D38=Sensorial!D37,0,IF(D38=Sensorial!D38,1,IF(D38=Sensorial!D39,4,IF(D38=Sensorial!D40,7)))) -> 0
B40: Field of view | C40: The extent of the observable virtual world at any given moment | D40: Select | E40: =IF(D40=Sensorial!D42,0,IF(D40=Sensorial!D43,3,IF(D40=Sensorial!D44,6,IF(D40=Sensorial!D45,7)))) -> 0
B42: Resolution | C42: Number of individual dots that can be placed in a 1 inch line | D42: Select | E42: =IF(D42=Sensorial!D47,0,IF(D42=Sensorial!D48,1,IF(D42=Sensorial!D49,2,IF(D42=Sensorial!D50,3,IF(D42=Sensorial!D51,4,IF(D42=Sensorial!D52,5,IF(D42=Sensorial!D53,6,IF(D42=Sensorial!D54,7)))))))) -> 0
B44: Frame rate | C44: Number of unique images shown per second | D44: Select | E44: =IF(D44=Sensorial!D56,0,IF(D44=Sensorial!D57,2.5,IF(D44=Sensorial!D58,5.5,IF(D44=Sensorial!D59,7)))) -> 0
B46: Audio | C46: The way sound travels through the user’s head | D46: Select | E46: =IF(D46=Sensorial!D61,0,IF(D46=Sensorial!D62,2.5,IF(D46=Sensorial!D63,5,IF(D46=Sensorial!D64,6,IF(D46=Sensorial!D65,7))))) -> 0
B48: Haptics | C48: Sense of touch or be touched by something in the virtual environment | D48: Select | E48: =IF(D48=Sensorial!D67,0,IF(D48=Sensorial!D68,1,IF(D48=Sensorial!D69,6.5,IF(D48=Sensorial!D70,6.5)))) -> 0
B50: Olfaction | C50: The sensation of perciving the smells | D50: Select | E50: =IF(D50=Sensorial!D72,0,IF(D50=Sensorial!D73,3,IF(D50=Sensorial!D74,6.5))) -> 0
E51: =AVERAGE(E24:E50) -> 0
C53: PRESENCE ESTIMATIVE: | E53: =AVERAGE(E17,E22,E51) -> 0

Sheet Engagemmmment
A2: Category | B2: Factor | C2: Description | D2: Level | E2: Value
A3: Engagement | B3: Inclusiveness | C3: The degree to which physical reality is excluded. | D3: Select | E3: 0
D4: None - Interference from the physical environment occurs throughout the entire virtual experience | E4: 2
D5: Partially - Interference from the physical environment occurs at some moments | E5: 5
D6: Totally - There is no interference from the physical environment | E6: 7
B8: Narrative | C8: The history designed to be virtually experienced by the user | D8: Select | E8: 0
D9: Incomplete - It does not present all elements of the narrative (fact, time, place, characters, cause, mode and consequence) | E9: 2.5
D10: Complete - Presents all elements of the narrative (fact, time, place, characters, cause, mode and consequence) | E10: 5
D11: Engaging - It has all the elements and includes at least one challenge, suspense, or surprising fact | E11: 6.5
B13: Attention | C13: The degree to which the virtual environment retains the user's attention. | D13: Select | E13: 0
D14: Alternating - Allows the user to switch attention to activities outside the experience | E14: 2.5
D15: Selective - Allows the user to switch attention, but, due to its attractiveness, maintains focus | E15: 5
D16: Concentrated - Requires total and exclusive concentration from the user | E16: 6
D17: Sustained - Requires the user's attention for an extended period without distractions | E17: 7
B19: Emotion | C19: The emotions (Anger, Sadness, Happiness, Disgust, Surprise, Fear) experienced by the user in the VE | D19: Select | E19: 0
D20: None - The VE does not cause emotions in the user | E20: 1
D21: Weak - Contemplates situations that cause week emotion in the user | E21: 3
D22: Medium - Contemplates situations that cause medium emotion in the user | E22: 5
D23: Strong - Contemplates situations that cause strong emotion in the user | E23: 7
B25: Task | C25: The act of doing something in the VE | D25: Select | E25: 0
D26: None - Requires no tasks beyond visualization | E26: 1
D27: Simple - Requires the execution of simple tasks | E27: 3
D28: Medium - Requires the execution of medium complexity tasks | E28: 5
D29: Complex - Requires the execution of complex tasks | E29: 7
B31: Copresence | C31: The feeling of being with another in a virtual environment | D31: Select | E31: 0
D32: None - There are no other actors in the VE | E32: 1
D33: Partial - There are other actors at some points in the experience | E33: 4
D34: Total - There are other actors throughout the entire experience | E34: 7
B36: Social presence | C36: The act of interacting with another in the virtual environment | D36: Select | E36: 0
D37: None - There is no interaction with other actors in VE | E37: 1
D38: Low - There is little interaction with other actors in VE | E38: 3
D39: Moderate - There is medium interaction with other actors in VE | E39: 5
D40: High - There is a lot of interaction with other actors in VE | E40: 7

Sheet Interactive
A1: Category | B1: Factor | C1: Description | D1: Level | E1: Value
A2: Interactive Fidelity | B2: Manipulation | C2: The ability of the VE to be modified by user actions | D2: Select | E2: 0
D3: None - Does not allow interaction | E3: 1
D4: Low Intuition - Enables non-intuitive interaction | E4: 4.5
D5: Intuitive - Enables intuitive interaction | E5: 5.5
D6: Very Intuitive - Enables very intuitive interaction | E6: 7
B8: Travel | C8: The way to navigate in the virtual environment | D8: Select | E8: 0
D9: None - The VE does not allow navigation | E9: 1
D10: Low Intuitiion - The way to navigate in the VE is not very intuitive (e.g. teleportation) | E10: 2
D11: Intuitive - The way to navigate in the VE is intuitive (e.g. joystick, fly, walk in place) | E11: 5
D12: Very Intuitive - The way to navigate in the VE is very intuitive (e.g. vehicle, real walk) | E12: 7
B14: * scale from 1 to 7, with 7 meaning that it contributes the most for eliciting a strong feeling of presence.

Sheet Sensorial
A2: Category | B2: Factor | C2: Description | D2: Level | E2: Value
A3: Sensorial Fidelity | B3: Invasiviness | C3: Number of external devices required | D3: Select | E3: 0
D4: High - More than four devices arranged over the user | E4: 1.5
D5: Moderate - Three or four devices arranged over the user | E5: 3.5
D6: Low - Up to two devices arranged over the user | E6: 5.5
D7: None - No devices against the user | E7: 7
B9: Proprioception | C9: Sense of self-movement and body position | D9: Select | E9: 0
D10: Absent - Proprioceptive feedback not provided | E10: 1
D11: Little - Proprioceptive feedback poorly provided | E11: 2.5
D12: Medim - Average proprioceptive feedback | E12: 4.5
D13: Total - Proprioceptive feedback very provided | E13: 6.5
B15: Body Ownership | C15: Sense of body ownership in the VE | D15: Select | E15: 0
D16: Absent - Does not provide the sense of body ownership | E16: 1.5
D17: Partial - Provides partial sense of body ownership | E17: 4.5
D18: Total - Provides total sense of body ownership | E18: 7
B20: Latency | C20: Delay between user action and the reaction of the virtual environment. | D20: Select | E20: 0
D21: Above 20 ms - Greater than 20 ms | E21: 1.5
D22: 10 - 20 ms - Between 10 and 20 ms | E22: 4.5
D23: 0 - 10 ms - Up to 10 ms | E23: 7
B25: Transition | C25: Change of state between the real and virtual world | D25: Select | E25: 0
D26: Instantaneous - Abrupt transition between real and virtual worlds | E26: 4
D27: Gradual - Gradual transition between real and virtual worlds | E27: 7
B29: Synchronization | C29: Coordination between user actions and all VE outputs | D29: Select | E29: 0
D30: Asynchronous - Does not present adequate visual, sound and interactional synchronization | E30: 3
D31: Synchronous - Shows synchronization between all stimuli | E31: 6.5
B33: Plausibility | C33: The extent to which VE is considered acceptable or admissible | D33: Select | E33: 0
D34: Inplausible - Inacceptable, inadmissible | E34: 3
D35: Plausible - Acceptable, admissible | E35: 6.5
B37: Visual Realism | C37: To what extent the VE looks visually real | D37: Select | E37: 0
D38: None - Does not provide geometric and lighting realism to objects. | E38: 1
D39: Static - Provides realism to objects when stationary | E39: 4
D40: Dinamic - Provides realism to objects even when in motion or altered | E40: 7
B42: Field of view | C42: The extent of observable virtual world at any given moment | D42: Select | E42: 0
D43: Up to 100º - Field of view up to 100º | E43: 3,0
D44: Up to 130º - Field of view up to 130º | E44: 6
D45: Up to 180º - Field of view up to 180º | E45: 7
B47: Resolution | C47: Number of individual dots that can be placed in a 1 inch line | D47: Select | E47: 0
D48: LDPI - Low density, 120 dots per inch | E48: 1
D49: MDPI - Medium density, 120–160 dots per inch | E49: 2
D50: TVDPI - Medium high density, 160–213 dots per inch | E50: 3
...

Sheet Form Responses 1
A1: Timestamp | B1: Untitled Question
